Workbook

Sheet Instructions
B2: INVARIANT-ANCHORED TELEMETRY (IAT)
B3: Platform: [Your Platform]
B4: For each universal invariant: specify what component emits the recommended telemetry, what detection signal indicates trouble, and what threats that signal catches.
B6: COLUMN GUIDE
B7: ID | C7: Stable identifier across the 50 invariants (G01–T10).
B8: Domain | C8: GHOST family this invariant belongs to.
B9: Global Invariant | C9: Universal property the platform must preserve. Anchored, not platform-specific.
B10: Surface | C10: Universal — which of the six surfaces (User, Interaction, Environment, Value, Content, Operations) this invariant anchors to. Framework-provided.
B11: Platform Implementation | C11: Platform-specific — the module, service, or subsystem that hosts this surface on your platform (e.g. game server, chat service). Use '—' when no surface exists yet.
B12: Recommended Telemetry | C12: Event name + key fields. The concrete observable artifact that proves or disproves the invariant.
B13: Detection Signal | C13: The pattern in the telemetry that indicates trouble. The filter expression, conceptually.
B14: Threat Examples | C14: 2–4 named threats this telemetry catches. Illustrative, not exhaustive.
B15: Invariant Status | C15: Active / Latent / Collapsed / Inactive (N/A). Where this invariant currently sits on the platform.
B16: Rationale | C16: One-line justification for the status decision. A reviewer should be able to challenge it from this alone.
B18: THE SIX SURFACES
B19: User | C19: Where an individual actor directly interacts with the platform.
B20: Interaction | C20: How actors interact with each other — communication, conflict, collaboration.
B21: Environment | C21: The shared, persistent state that all actors operate within.
B22: Value | C22: Economy, assets, transactions, entitlements, transferable worth.
B23: Content | C23: Everything created, uploaded, or published by users or the system.
B24: Operations | C24: Backend services, infrastructure — the technical substrate.
B26: STATUS TAXONOMY
B27: Active | C27: Telemetry exists, queryable, and threat catalog binds to it.
B28: Latent | C28: Telemetry specified but not emitted, or emitted but not queryable.
B29: Collapsed | C29: Invariant has no independent telemetry — its observability is fully covered by another invariant's signals.
B30: Inactive (N/A) | C30: No surface exists, so no telemetry required. Decision is recorded for review.

Sheet IAT Invariants
A1: ID | B1: Domain | C1: Global Invariant | D1: Surface | E1: Platform Implementation | F1: Recommended Telemetry | G1: Detection Signal | H1: Threat Examples | I1: Invariant Status | J1: Rationale
A2: G01 | B2: Gameplay | C2: The server must be the final authority over outcomes | D2: Environment | F2: server_validated_action { player_id, action, server_state_hash, validation_outcome, ts } | G2: validation_outcome != 'pass' OR client_claim != server_truth | H2: Outcome spoofing · Win-claim forgery · Score injection
A3: G02 | B3: Gameplay | C3: Player inputs must not produce super-human performance | D3: User | F3: input_rate_sample { player_id, action_type, count_per_window, window_ms } | G3: count_per_window > human_p99_threshold sustained over N windows | H3: Input automation · Macro use · Aim-bot / move-bot
A4: G03 | B4: Gameplay | C4: Game rules must be enforced consistently across players | D4: Environment | F4: rule_evaluation { player_id, rule_id, decision, ts } | G4: Same rule_id producing divergent decisions for equivalent inputs | H4: Rule bypass · Privileged-account drift · A/B-config leak
A5: G04 | B5: Gameplay | C5: Game state must remain synchronized for all participants | D5: Environment | F5: state_sync_event { session_id, server_state_hash, client_state_hash, ts } | G5: client_state_hash != server_state_hash for any participant | H5: Desync exploitation · State injection · Phantom moves
A6: G05 | B6: Gameplay | C6: Timing must not be exploitable for competitive advantage | D6: User | F6: action_timing { player_id, action_id, server_ts, client_ts, drift_ms } | G6: drift_ms outside tolerance OR action burst within race window | H6: Lag-switching · Race-condition exploit · Time-warp
A7: G06 | B7: Gameplay | C7: Progression must only advance through legitimate gameplay | D7: Environment | F7: progression_change { player_id, prior_state, new_state, derived_from_action_id } | G7: new_state without matching validated action_id in lineage | H7: Save-state injection · Progression skipping · Achievement forgery
A8: G07 | B8: Gameplay | C8: Randomized mechanics must not be predictable or manipulable | D8: Environment | F8: rng_draw { draw_id, seed_source, output, consumer_action_id } | G8: seed_source predictable OR output distribution skewed | H8: RNG seed prediction · Reroll abuse · Drop-rate manipulation
A9: G08 | B9: Gameplay | C9: Actions must not be replayed to gain additional benefit | D9: User | F9: action_submission { action_id, nonce, player_id, session_id, ts } | G9: Repeated nonce or action_id within active session | H9: Replay attack · Duplicate-move exploit · Token reuse
A10: G09 | B10: Gameplay | C10: Client-reported state must never be blindly trusted | D10: User | F10: client_claim { player_id, claim_type, claim_value } + server reconciliation outcome | G10: Server reconciles to a different value OR rejects claim | H10: Client-side cheating · Memory editing · State forgery
A11: G10 | B11: Gameplay | C11: Non-production or debug paths must not affect live gameplay | D11: Operations | F11: code_path_invocation { path_id, env_tag, caller, ts } | G11: env_tag == 'debug' invoked from production session | H11: Debug-flag abuse · Cheat-menu access · QA tooling exposure
A12: H01 | B12: Harm & Safety | C12: Player expression must not cause harm to others | D12: Interaction | F12: expression_event { source_player_id, recipient_scope, content_ref, classifier_score, ts } | G12: classifier_score crosses threshold OR no classifier output emitted | H12: Targeted harassment · Slur in chat · Coordinated brigading
A13: H02 | B13: Harm & Safety | C13: Harmful behavior patterns must be detectable over time | D13: User | F13: behavior_score_update { player_id, window, signal_type, score, ts } | G13: Cumulative score rising or repeated signals within window | H13: Repeat offender · Slow-burn harassment · Boundary-testing
... A51: T10 | B51: Trade & Economy | C51: Economy-wide anomalies must be detectable | D51: Value | F51: economy_health_sample { metric, value, baseline, anomaly_score, ts } | G51: anomaly_score above threshold for any economy_health metric | H51: Hyperinflation · Sudden scarcity · Currency drain · Market shock

Sheet Summary
B2: ACTIVATION SUMMARY
B3: Platform: [Your Platform]
B4: Updates automatically from the IAT Invariants sheet.
B6: Total | C6: Active | D6: Latent | E6: Collapsed | F6: Inactive (N/A)
B7: =COUNTA('IAT Invariants'!A2:A51) -> 50 | C7: =COUNTIF('IAT Invariants'!I2:I51,"Active") -> 0 | D7: =COUNTIF('IAT Invariants'!I2:I51,"Latent") -> 0 | E7: =COUNTIF('IAT Invariants'!I2:I51,"Collapsed") -> 0 | F7: =COUNTIF('IAT Invariants'!I2:I51,"Inactive (N/A)") -> 0
B10: SURFACE × STATUS
B11: Surface | C11: Active | D11: Latent | E11: Collapsed | F11: Inactive (N/A) | G11: Total
B12: User | C12: =COUNTIFS('IAT Invariants'!D:D,"User",'IAT Invariants'!I:I,"Active") -> 0 | D12: =COUNTIFS('IAT Invariants'!D:D,"User",'IAT Invariants'!I:I,"Latent") -> 0 | E12: =COUNTIFS('IAT Invariants'!D:D,"User",'IAT Invariants'!I:I,"Collapsed") -> 0 | F12: =COUNTIFS('IAT Invariants'!D:D,"User",'IAT Invariants'!I:I,"Inactive (N/A)") -> 0 | G12: =COUNTIF('IAT Invariants'!D:D,"User") -> 10
B13: Interaction | C13: =COUNTIFS('IAT Invariants'!D:D,"Interaction",'IAT Invariants'!I:I,"Active") -> 0 | D13: =COUNTIFS('IAT Invariants'!D:D,"Interaction",'IAT Invariants'!I:I,"Latent") -> 0 | E13: =COUNTIFS('IAT Invariants'!D:D,"Interaction",'IAT Invariants'!I:I,"Collapsed") -> 0 | F13: =COUNTIFS('IAT Invariants'!D:D,"Interaction",'IAT Invariants'!I:I,"Inactive (N/A)") -> 0 | G13: =COUNTIF('IAT Invariants'!D:D,"Interaction") -> 8
B14: Environment | C14: =COUNTIFS('IAT Invariants'!D:D,"Environment",'IAT Invariants'!I:I,"Active") -> 0 | D14: =COUNTIFS('IAT Invariants'!D:D,"Environment",'IAT Invariants'!I:I,"Latent") -> 0 | E14: =COUNTIFS('IAT Invariants'!D:D,"Environment",'IAT Invariants'!I:I,"Collapsed") -> 0 | F14: =COUNTIFS('IAT Invariants'!D:D,"Environment",'IAT Invariants'!I:I,"Inactive (N/A)") -> 0 | G14: =COUNTIF('IAT Invariants'!D:D,"Environment") -> 5
B15: Value | C15: =COUNTIFS('IAT Invariants'!D:D,"Value",'IAT Invariants'!I:I,"Active") -> 0 | D15: =COUNTIFS('IAT Invariants'!D:D,"Value",'IAT Invariants'!I:I,"Latent") -> 0 | E15: =COUNTIFS('IAT Invariants'!D:D,"Value",'IAT Invariants'!I:I,"Collapsed") -> 0 | F15: =COUNTIFS('IAT Invariants'!D:D,"Value",'IAT Invariants'!I:I,"Inactive (N/A)") -> 0 | G15: =COUNTIF('IAT Invariants'!D:D,"Value") -> 10
B16: Content | C16: =COUNTIFS('IAT Invariants'!D:D,"Content",'IAT Invariants'!I:I,"Active") -> 0 | D16: =COUNTIFS('IAT Invariants'!D:D,"Content",'IAT Invariants'!I:I,"Latent") -> 0 | E16: =COUNTIFS('IAT Invariants'!D:D,"Content",'IAT Invariants'!I:I,"Collapsed") -> 0 | F16: =COUNTIFS('IAT Invariants'!D:D,"Content",'IAT Invariants'!I:I,"Inactive (N/A)") -> 0 | G16: =COUNTIF('IAT Invariants'!D:D,"Content") -> 2
B17: Operations | C17: =COUNTIFS('IAT Invariants'!D:D,"Operations",'IAT Invariants'!I:I,"Active") -> 0 | D17: =COUNTIFS('IAT Invariants'!D:D,"Operations",'IAT Invariants'!I:I,"Latent") -> 0 | E17: =COUNTIFS('IAT Invariants'!D:D,"Operations",'IAT Invariants'!I:I,"Collapsed") -> 0 | F17: =COUNTIFS('IAT Invariants'!D:D,"Operations",'IAT Invariants'!I:I,"Inactive (N/A)") -> 0 | G17: =COUNTIF('IAT Invariants'!D:D,"Operations") -> 15
B20: DOMAIN × STATUS
B21: Domain | C21: Active | D21: Latent | E21: Collapsed | F21: Inactive (N/A) | G21: Total
B22: Gameplay | C22: =COUNTIFS('IAT Invariants'!B:B,"Gameplay",'IAT Invariants'!I:I,"Active") -> 0 | D22: =COUNTIFS('IAT Invariants'!B:B,"Gameplay",'IAT Invariants'!I:I,"Latent") -> 0 | E22: =COUNTIFS('IAT Invariants'!B:B,"Gameplay",'IAT Invariants'!I:I,"Collapsed") -> 0 | F22: =COUNTIFS('IAT Invariants'!B:B,"Gameplay",'IAT Invariants'!I:I,"Inactive (N/A)") -> 0 | G22: =COUNTIF('IAT Invariants'!B:B,"Gameplay") -> 10
B23: Harm & Safety | C23: =COUNTIFS('IAT Invariants'!B:B,"Harm & Safety",'IAT Invariants'!I:I,"Active") -> 0 | D23: =COUNTIFS('IAT Invariants'!B:B,"Harm & Safety",'IAT Invariants'!I:I,"Latent") -> 0 | E23: =COUNTIFS('IAT Invariants'!B:B,"Harm & Safety",'IAT Invariants'!I:I,"Collapsed") -> 0 | F23: =COUNTIFS('IAT Invariants'!B:B,"Harm & Safety",'IAT Invariants'!I:I,"Inactive (N/A)") -> 0 | G23: =COUNTIF('IAT Invariants'!B:B,"Harm & Safety") -> 10
B24: Operations | C24: =COUNTIFS('IAT Invariants'!B:B,"Operations",'IAT Invariants'!I:I,"Active") -> 0 | D24: =COUNTIFS('IAT Invariants'!B:B,"Operations",'IAT Invariants'!I:I,"Latent") -> 0 | E24: =COUNTIFS('IAT Invariants'!B:B,"Operations",'IAT Invariants'!I:I,"Collapsed") -> 0 | F24: =COUNTIFS('IAT Invariants'!B:B,"Operations",'IAT Invariants'!I:I,"Inactive (N/A)") -> 0 | G24: =COUNTIF('IAT Invariants'!B:B,"Operations") -> 10
B25: Social Systems | C25: =COUNTIFS('IAT Invariants'!B:B,"Social Systems",'IAT Invariants'!I:I,"Active") -> 0 | D25: =COUNTIFS('IAT Invariants'!B:B,"Social Systems",'IAT Invariants'!I:I,"Latent") -> 0 | E25: =COUNTIFS('IAT Invariants'!B:B,"Social Systems",'IAT Invariants'!I:I,"Collapsed") -> 0 | F25: =COUNTIFS('IAT Invariants'!B:B,"Social Systems",'IAT Invariants'!I:I,"Inactive (N/A)") -> 0 | G25: =COUNTIF('IAT Invariants'!B:B,"Social Systems") -> 10
B26: Trade & Economy | C26: =COUNTIFS('IAT Invariants'!B:B,"Trade & Economy",'IAT Invariants'!I:I,"Active") -> 0 | D26: =COUNTIFS('IAT Invariants'!B:B,"Trade & Economy",'IAT Invariants'!I:I,"Latent") -> 0 | E26: =COUNTIFS('IAT Invariants'!B:B,"Trade & Economy",'IAT Invariants'!I:I,"Collapsed") -> 0 | F26: =COUNTIFS('IAT Invariants'!B:B,"Trade & Economy",'IAT Invariants'!I:I,"Inactive (N/A)") -> 0 | G26: =COUNTIF('IAT Invariants'!B:B,"Trade & Economy") -> 10
B31: TEST OUTCOMES
B32: Total | C32: Pass | D32: Fail | E32: Pending | F32: N/A
B33: =COUNTA('Test Traceability'!C2:C151) -> 150 | C33: =COUNTIF('Test Traceability'!F2:F151,"PASS") -> 0 | D33: =COUNTIF('Test Traceability'!F2:F151,"FAIL") -> 0 | E33: =COUNTIF('Test Traceability'!F2:F151,"PENDING") -> 0 | F33: =COUNTIF('Test Traceability'!F2:F151,"N/A") -> 0

Sheet Test Traceability
A1: Inv ID | B1: Telemetry Event | C1: Test ID | D1: Kind | E1: Test Assertion | F1: Test Outcome | G1: Threats Caught | H1: Notes
A2: G01 | B2: server_validated_action | C2: T-G01-01 | D2: EXISTENCE | E2: Event emits on every player action submitted to the server. | G2: Outcome spoofing · Win-claim forgery · Score injection | H2: Activation: Active
C3: T-G01-02 | D3: SCHEMA | E3: Fields { player_id, action, server_state_hash, validation_outcome, ts } all populated.
C4: T-G01-03 | D4: FILTER | E4: Filter validation_outcome != 'pass' OR client_claim != server_truth fires on synthetic bad inputs.
A5: G02 | B5: input_rate_sample | C5: T-G02-01 | D5: EXISTENCE | E5: Event emits per action-type per player per window. | G5: Input automation · Macro use · Aim-bot / move-bot | H5: Activation: Active
C6: T-G02-02 | D6: SCHEMA | E6: Fields { player_id, action_type, count_per_window, window_ms } all populated.
C7: T-G02-03 | D7: FILTER | E7: Filter count_per_window > human_p99 fires on macro/bot input traces.
A8: G03 | B8: rule_evaluation | C8: T-G03-01 | D8: EXISTENCE | E8: Event emits on every rule check, allowed or denied. | G8: Rule bypass · Privileged-account drift · A/B-config leak | H8: Activation: Active
C9: T-G03-02 | D9: SCHEMA | E9: Fields { player_id, rule_id, decision, ts } all populated.
C10: T-G03-03 | D10: FILTER | E10: Filter detects divergent decisions for equivalent inputs across players.
A11: G04 | B11: state_sync_event | C11: T-G04-01 | D11: EXISTENCE | E11: Event emits per sync tick or after every authoritative state change. | G11: Desync exploitation · State injection · Phantom moves | H11: Activation: Active
C12: T-G04-02 | D12: SCHEMA | E12: Fields { session_id, server_state_hash, client_state_hash, ts } populated.
C13: T-G04-03 | D13: FILTER | E13: Filter client_state_hash != server_state_hash fires on injected divergence.
A14: G05 | B14: action_timing | C14: T-G05-01 | D14: EXISTENCE | E14: Event emits with timing context for every server-bound action. | G14: Lag-switching · Race-condition exploit · Time-warp | H14: Activation: Collapsed
C15: T-G05-02 | D15: SCHEMA | E15: Fields { player_id, action_id, server_ts, client_ts, drift_ms } populated.
C16: T-G05-03 | D16: FILTER | E16: Filter drift_ms outside tolerance fires; folds into G02 rate logic.
A17: G06 | B17: progression_change | C17: T-G06-01 | D17: EXISTENCE | E17: Event emits on every persistent player progression mutation. | G17: Save-state injection · Progression skipping · Achievement forgery | H17: Activation: Active
C18: T-G06-02 | D18: SCHEMA | E18: Fields { player_id, prior_state, new_state, derived_from_action_id } populated.
C19: T-G06-03 | D19: FILTER | E19: Filter detects new_state without matching validated action_id lineage.
A20: G07 | B20: rng_draw | C20: T-G07-01 | D20: EXISTENCE | E20: Event emits when an authoritative RNG draw happens. | G20: RNG seed prediction · Reroll abuse · Drop-rate manipulation | H20: Activation: Inactive (N/A)
C21: T-G07-02 | D21: SCHEMA | E21: Fields { draw_id, seed_source, output, consumer_action_id } populated.
C22: T-G07-03 | D22: FILTER | E22: Filter detects predictable seed_source or skewed output distribution.
A23: G08 | B23: action_submission | C23: T-G08-01 | D23: EXISTENCE | E23: Event emits for every action submitted to the server. | G23: Replay attack · Duplicate-move exploit · Token reuse | H23: Activation: Active
C24: T-G08-02 | D24: SCHEMA | E24: Fields { action_id, nonce, player_id, session_id, ts } populated.
C25: T-G08-03 | D25: FILTER | E25: Filter detects repeated nonce or action_id within active session.
A26: G09 | B26: client_claim | C26: T-G09-01 | D26: EXISTENCE | E26: Event emits whenever a client asserts state; reconciliation outcome attached. | G26: Client-side cheating · Memory editing · State forgery | H26: Activation: Active
C27: T-G09-02 | D27: SCHEMA | E27: Fields { player_id, claim_type, claim_value, reconciliation_outcome } populated.
C28: T-G09-03 | D28: FILTER | E28: Filter detects reconciliation_outcome != 'accepted' or value mismatches.
A29: G10 | B29: code_path_invocation | C29: T-G10-01 | D29: EXISTENCE | E29: Event emits on entry to any tagged debug path. | G29: Debug-flag abuse · Cheat-menu access · QA tooling exposure | H29: Activation: Collapsed
C30: T-G10-02 | D30: SCHEMA | E30: Fields { path_id, env_tag, caller, ts } populated.
C31: T-G10-03 | D31: FILTER | E31: Filter env_tag == 'debug' invoked from production session triggers.
A32: H01 | B32: expression_event | C32: T-H01-01 | D32: EXISTENCE | E32: Event emits for every chat message, including private/whispered. | G32: Targeted harassment · Slur in chat · Coordinated brigading | H32: Activation: Active
C33: T-H01-02 | D33: SCHEMA | E33: Fields { source_player_id, recipient_scope, content_ref, classifier_score, ts } populated.
C34: T-H01-03 | D34: FILTER | E34: Filter classifier_score crosses threshold OR no classifier output emitted.
A35: H02 | B35: behavior_score_update | C35: T-H02-01 | D35: EXISTENCE | E35: Event emits when behavior signal updates for a player. | G35: Repeat offender · Slow-burn harassment · Boundary-testing | H35: Activation: Active
C36: T-H02-02 | D36: SCHEMA | E36: Fields { player_id, window, signal_type, score, ts } populated.
C37: T-H02-03 | D37: FILTER | E37: Filter detects cumulative score rising or repeated signals within window.
A38: H03 | B38: age_gated_interaction | C38: T-H03-01 | D38: EXISTENCE | E38: Event emits when an actor targets a recipient on an age-gated action. | G38: Grooming pattern · Age-gap targeting · Unsolicited contact | H38: Activation: Inactive (N/A)
C39: T-H03-02 | D39: SCHEMA | E39: Fields { actor_player_id, target_player_id, target_age_bracket, action, ts } populated.
C40: T-H03-03 | D40: FILTER | E40: Filter adult actor targeting minor with restricted action fires.
...
